<?xml version="1.0"?>
<robot name="multi_object">

  <material name="Black">
    <color rgba="0.0 0.0 0.0 1.0"/>
  </material>
  <material name="Blue">
    <color rgba="0.0 0.0 0.8 1.0"/>
  </material>
  <material name="Green">
    <color rgba="0.0 0.9 0.0 1.0"/>
  </material>
  <material name="Grey">
    <color rgba="0.4 0.4 0.4 1.0"/>
  </material>
  <material name="Glas">
    <color rgba="0.4 0.4 0.4 0.1"/>
  </material>
  <material name="Orange">
    <color rgba="1.0 0.423529411765 0.0392156862745 1.0"/>
  </material>
  <material name="Brown">
    <color rgba="0.870588235294 0.811764705882 0.764705882353 1.0"/>
  </material>
  <material name="Red">
    <color rgba="0.8 0.0 0.0 1.0"/>
  </material>
  <material name="White">
    <color rgba="1.0 1.0 1.0 1.0"/>
  </material>
  <material name="Silver">
    <color rgba="0.82 0.82 0.82 1.0"/>
  </material>


  <link name="base">
    <visual>
      <origin xyz="0 0 0" rpy="0 0 0" />
      <geometry>
        <box size="0.01 0.01 0.01" />
      </geometry>
    </visual>
  </link>

  <joint name="base_to_object_0" type="floating">
    <parent link="base"/>
    <child link="object_0"/>
    <origin rpy="0 0 0" xyz="0 0 0"/>
  </joint>

  <link name="object_0">
    <visual>
      <origin xyz="0 0 0" rpy="0 0 0" />
      <geometry>
        <box size="0.1 0.05 0.05" />
      </geometry>
      <material name="Red"/>
    </visual>
  </link>

  <joint name="base_to_object_1" type="floating">
    <parent link="base"/>
    <child link="object_1"/>
    <origin rpy="0 0 0" xyz="0 0 0"/>
  </joint>

  <link name="object_1">
    <visual>
      <origin xyz="0 0 0" rpy="0 1.57 0" />
      <geometry>
        <cylinder length="0.130" radius="0.0325" />
      </geometry>
      <material name="Green"/>
    </visual>
    <collision>
      <geometry>
        <cylinder length="0.130" radius="0.0325" />
      </geometry>
    </collision>
  </link>

  <joint name="base_to_object_2" type="floating">
    <parent link="base"/>
    <child link="object_2"/>
    <origin rpy="0 0 0" xyz="0 0 0"/>
  </joint>

  <link name="object_2">
    <visual>
      <origin xyz="0 0 0" rpy="0 0 0" />git
      <geometry>
        <box size="0.06 0.06 0.06" />
      </geometry>
      <material name="Blue"/>
    </visual>
     <collision>
      <geometry>
        <box size="0.059 0.059 0.056" />
      </geometry>
    </collision>
    <collision>
      <origin xyz="-0.03 -0.03 -0.03" rpy="0 0 0"/>
      <geometry>
        <sphere radius="1e-7"/>
      </geometry>
    </collision>
    <collision>
      <origin xyz="-0.03 0.03 -0.03" rpy="0 0 0"/>
      <geometry>
        <sphere radius="1e-7"/>
      </geometry>
    </collision>
    <collision>
      <origin xyz="0.03 0.03 -0.03" rpy="0 0 0"/>
      <geometry>
        <sphere radius="1e-7"/>
      </geometry>
    </collision>
    <collision>
      <origin xyz="0.03 -0.03 -0.03" rpy="0 0 0"/>
      <geometry>
        <sphere radius="1e-7"/>
      </geometry>
    </collision>
    <collision>
      <origin xyz="-0.03 -0.03 0.03" rpy="0 0 0"/>
      <geometry>
        <sphere radius="1e-7"/>
      </geometry>
    </collision>
    <collision>
      <origin xyz="-0.03 0.03 0.03" rpy="0 0 0"/>
      <geometry>
        <sphere radius="1e-7"/>
      </geometry>
    </collision>
    <collision>
      <origin xyz="0.03 0.03 0.03" rpy="0 0 0"/>
      <geometry>
        <sphere radius="1e-7"/>
      </geometry>
    </collision>
    <collision>
      <origin xyz="0.03 -0.03 0.03" rpy="0 0 0"/>
      <geometry>
        <sphere radius="1e-7"/>
      </geometry>
    </collision>
  </link>

</robot>
