<?xml version="1.0"?>
<robot name="multi_object_2">

  <material name="Black">
    <color rgba="0.0 0.0 0.0 1.0"/>
  </material>
  <material name="Blue">
    <color rgba="0.0 0.0 0.8 1.0"/>
  </material>
  <material name="Green">
    <color rgba="0.5 1.0 0.3 1.0"/>
  </material>
  <material name="Cyan">
    <color rgba="0.0 0.6 0.6 1.0"/>
  </material>
  <material name="Grey">
    <color rgba="0.4 0.4 0.4 1.0"/>
  </material>
  <material name="Yellow">
    <color rgba="0.6 0.6 0.0 1.0"/>
  </material>
  <material name="Glas">
    <color rgba="0.4 0.4 0.4 0.1"/>
  </material>
  <material name="Orange">
    <color rgba="1.0 0.423529411765 0.0392156862745 1.0"/>
  </material>
  <material name="Brown">
    <color rgba="0.870588235294 0.811764705882 0.764705882353 1.0"/>
  </material>
  <material name="Red">
    <color rgba="0.8 0.0 0.0 1.0"/>
  </material>
  <material name="Purple">
    <color rgba="0.8 0.0 0.8 1.0"/>
  </material>
  <material name="White">
    <color rgba="1.0 1.0 1.0 1.0"/>
  </material>
  <material name="Silver">
    <color rgba="0.82 0.82 0.82 1.0"/>
  </material>


  <link name="base">
    <visual>
      <origin xyz="0 0 0" rpy="0 0 0" />
      <geometry>
        <box size="0.01 0.01 0.01" />
      </geometry>
    </visual>
  </link>

  <joint name="base_to_object_0" type="floating">
    <parent link="base"/>
    <child link="object_0"/>
    <origin rpy="0 0 0" xyz="0 0 0"/>
  </joint>

  <link name="object_0">
    <visual>
      <origin xyz="0 0 0" rpy="0 1.57 0" />
      <geometry>
        <cylinder length="0.130" radius="0.0325" />
      </geometry>
      <material name="Cyan"/>
    </visual>
    <collision>
      <geometry>
        <cylinder length="0.130" radius="0.0325" />
      </geometry>
    </collision>
  </link>

  <joint name="base_to_object_1" type="floating">
    <parent link="base"/>
    <child link="object_1"/>
    <origin rpy="0 0 0" xyz="0 0 0"/>
  </joint>

  <link name="object_1">
    <visual>
      <origin xyz="0 0 0" rpy="0 0 0" />
      <geometry>
        <box size="0.1 0.05 0.05" />
      </geometry>
      <material name="Black"/>
    </visual>
  </link>

  <joint name="base_to_object_2" type="floating">
    <parent link="base"/>
    <child link="object_2"/>
    <origin rpy="0 0 0" xyz="0 0 0"/>
  </joint>

  <link name="object_2">
    <visual>
      <origin xyz="0 0 0" rpy="0 0 0" />git
      <geometry>
        <box size="0.06 0.06 0.06" />
      </geometry>
      <material name="Yellow"/>
    </visual>
  </link>

  <joint name="base_to_object_3" type="floating">
    <parent link="base"/>
    <child link="object_3"/>
    <origin rpy="0 0 0" xyz="0 0 0"/>
  </joint>

  <link name="object_3">
   <visual>
      <origin xyz="0 0 0" rpy="0 0 0" />
      <geometry>
        <sphere radius="0.0325"/>
      </geometry>
      <material name="Orange"/>
    </visual>
    <collision>
      <geometry>
        <sphere radius="0.0325"/>
      </geometry>
    </collision>
  </link>


  <joint name="base_to_object_4" type="floating">
    <parent link="base"/>
    <child link="object_4"/>
    <origin rpy="0 0 0" xyz="0 0 0"/>
  </joint>

  <link name="object_4">
    <visual>
      <origin xyz="0 0 0" rpy="0 1.57 0" />
      <geometry>
        <cylinder length="0.130" radius="0.0325" />
      </geometry>
      <material name="Purple"/>
    </visual>
    <collision>
      <geometry>
        <cylinder length="0.130" radius="0.0325" />
      </geometry>
    </collision>
  </link>


  <joint name="base_to_object_5" type="floating">
    <parent link="base"/>
    <child link="object_5"/>
    <origin rpy="0 0 0" xyz="0 0 0"/>
  </joint>

  <link name="object_5">
    <visual>
      <origin xyz="0 0 0" rpy="0 1.57 0" />
      <geometry>
        <cylinder length="0.130" radius="0.0325" />
      </geometry>
      <material name="Silver"/>
    </visual>
    <collision>
      <geometry>
        <cylinder length="0.130" radius="0.0325" />
      </geometry>
    </collision>
  </link>


  <joint name="base_to_object_6" type="floating">
    <parent link="base"/>
    <child link="object_6"/>
    <origin rpy="0 0 0" xyz="0 0 0"/>
  </joint>

  <link name="object_6">
    <visual>
      <origin xyz="0 0 0" rpy="0 0 0" />
      <geometry>
        <box size="0.1 0.05 0.05" />
      </geometry>
      <material name="Grey"/>
    </visual>
    <collision>
      <geometry>
        <box size="0.099 0.034 0.179" />
      </geometry>
    </collision>
  </link>



</robot>
