<?xml version="1.0" ?>
<!-- =================================================================================== -->
<!-- |    This document was autogenerated by xacro from cassie.xacro                   | -->
<!-- |    EDITING THIS FILE BY HAND IS NOT RECOMMENDED                                 | -->
<!-- =================================================================================== -->
<!-- Author: Ross Hartley
	 Email:  rosshart@umich.edu
     Date:   04/24/2016   -->
<robot name="cassie" xmlns:xacro="http://ros.org/wiki/xacro">

<!-- VectorNav is a child of pelvis. THis should be flipped? -->
  <!-- <link name="vectorNav">
    
  </link> -->
  <link name="pelvis">
    <visual>
      <origin rpy="0 0 0" xyz="0 0 0"/>
      <geometry>
        <mesh filename="package://cassie_description/meshes/pelvis.obj" scale="1 1 1"/>
      </geometry>
      <material name="grey">
        <color rgba="0.35 0.35 0.35 1"/>
      </material>
    </visual>
    <!-- <inertial>
      <mass value="1.2"/>
      <inertia ixx="1.0" ixy="0.0" ixz="0.0" iyy="1.0" iyz="0.0" izz="1.0"/>
    </inertial> -->
  </link>
  <link name="left_pelvis_abduction">
    <visual>
      <origin rpy="0 0 0" xyz="0 0 0"/>
      <geometry>
        <mesh filename="package://cassie_description/meshes/abduction.obj" scale="1 1 1"/>
      </geometry>
      <material name="light_grey">
        <color rgba="0.75 0.75 0.75 1"/>
      </material>
    </visual>
  </link>
  <link name="left_pelvis_rotation">
    <visual>
      <origin rpy="0 0 0" xyz="0 0 0"/>
      <geometry>
        <mesh filename="package://cassie_description/meshes/yaw.obj" scale="1 1 1"/>
      </geometry>
      <material name="light_grey">
        <color rgba="0.75 0.75 0.75 1"/>
      </material>
    </visual>
  </link>
  <link name="left_hip">
    <visual>
      <origin rpy="0 0 0" xyz="0 0 0"/>
      <geometry>
        <mesh filename="package://cassie_description/meshes/hip.obj" scale="1 1 1"/>
      </geometry>
      <material name="light_grey">
        <color rgba="0.75 0.75 0.75 1"/>
      </material>
    </visual>
  </link>
  <link name="left_thigh">
    <visual>
      <origin rpy="0 0 0" xyz="0 0 0"/>
      <geometry>
        <mesh filename="package://cassie_description/meshes/thigh.obj" scale="1 1 1"/>
      </geometry>
      <material name="light_grey">
        <color rgba="0.75 0.75 0.75 1"/>
      </material>
    </visual>
  </link>
  <link name="left_knee">
    <visual>
      <origin rpy="0 0 0" xyz="0 0 0"/>
      <geometry>
        <mesh filename="package://cassie_description/meshes/knee-output.obj" scale="1 1 1"/>
      </geometry>
      <material name="grey">
        <color rgba="0.35 0.35 0.35 1"/>
      </material>
    </visual>
  </link>
  <link name="left_shin">
    <visual>
      <origin rpy="0 0 0" xyz="0 0 0"/>
      <geometry>
        <mesh filename="package://cassie_description/meshes/shin-bone.obj" scale="1 1 1"/>
      </geometry>
      <material name="grey">
        <color rgba="0.35 0.35 0.35 1"/>
      </material>
    </visual>
  </link>
  <link name="left_tarsus">
    <visual>
      <origin rpy="0 0 0" xyz="0 0 0"/>
      <geometry>
        <mesh filename="package://cassie_description/meshes/tarsus.obj" scale="1 1 1"/>
      </geometry>
      <material name="grey">
        <color rgba="0.35 0.35 0.35 1"/>
      </material>
    </visual>
  </link>
  <link name="left_toe">
    <visual>
      <origin rpy="0 0 0" xyz="0 0 0"/>
      <geometry>
        <mesh filename="package://cassie_description/meshes/toe.obj" scale="1 1 1"/>
      </geometry>
      <material name="light_grey">
        <color rgba="0.75 0.75 0.75 1"/>
      </material>
    </visual>
    <inertial>
      <mass value="0.01"/>
      <inertia ixx="1.0" ixy="0.0" ixz="0.0" iyy="1.0" iyz="0.0" izz="1.0"/>
    </inertial>
  </link>



  <link name="right_pelvis_abduction">
    <visual>
      <origin rpy="0 0 0" xyz="0 0 0"/>
      <geometry>
        <mesh filename="package://cassie_description/meshes/abduction_mirror.obj" scale="1 1 1"/>
      </geometry>
      <material name="light_grey">
        <color rgba="0.75 0.75 0.75 1"/>
      </material>
    </visual>
  </link>
  <link name="right_pelvis_rotation">
    <visual>
      <origin rpy="0 0 0" xyz="0 0 0"/>
      <geometry>
        <mesh filename="package://cassie_description/meshes/yaw_mirror.obj" scale="1 1 1"/>
      </geometry>
      <material name="light_grey">
        <color rgba="0.75 0.75 0.75 1"/>
      </material>
    </visual>
  </link>
  <link name="right_hip">
    <visual>
      <origin rpy="0 0 0" xyz="0 0 0"/>
      <geometry>
        <mesh filename="package://cassie_description/meshes/hip_mirror.obj" scale="1 1 1"/>
      </geometry>
      <material name="light_grey">
        <color rgba="0.75 0.75 0.75 1"/>
      </material>
    </visual>
  </link>
  <link name="right_thigh">
    <visual>
      <origin rpy="0 0 0" xyz="0 0 0"/>
      <geometry>
        <mesh filename="package://cassie_description/meshes/thigh_mirror.obj" scale="1 1 1"/>
      </geometry>
      <material name="light_grey">
        <color rgba="0.75 0.75 0.75 1"/>
      </material>
    </visual>
  </link>
  <link name="right_knee">
    <visual>
      <origin rpy="0 0 0" xyz="0 0 0"/>
      <geometry>
        <mesh filename="package://cassie_description/meshes/knee-output_mirror.obj" scale="1 1 1"/>
      </geometry>
      <material name="grey">
        <color rgba="0.35 0.35 0.35 1"/>
      </material>
    </visual>
  </link>
  <link name="right_shin">
    <visual>
      <origin rpy="0 0 0" xyz="0 0 0"/>
      <geometry>
        <mesh filename="package://cassie_description/meshes/shin-bone_mirror.obj" scale="1 1 1"/>
      </geometry>
      <material name="grey">
        <color rgba="0.35 0.35 0.35 1"/>
      </material>
    </visual>
  </link>
  <link name="right_tarsus">
    <visual>
      <origin rpy="0 0 0" xyz="0 0 0"/>
      <geometry>
        <mesh filename="package://cassie_description/meshes/tarsus_mirror.obj" scale="1 1 1"/>
      </geometry>
      <material name="grey">
        <color rgba="0.35 0.35 0.35 1"/>
      </material>
    </visual>
  </link>
  <link name="right_toe">
    <visual>
      <origin rpy="0 0 0" xyz="0 0 0"/>
      <geometry>
        <mesh filename="package://cassie_description/meshes/toe_mirror.obj" scale="1 1 1"/>
      </geometry>
      <material name="light_grey">
        <color rgba="0.75 0.75 0.75 1"/>
      </material>
    </visual>
    <inertial>
      <mass value="0.01"/>
      <inertia ixx="1.0" ixy="0.0" ixz="0.0" iyy="1.0" iyz="0.0" izz="1.0"/>
    </inertial>
  </link>

  <!-- <joint name="fixed_pelvis_to_vectorNav" type="fixed">
    <origin rpy="0 0 0" xyz="0.03155 0 -0.07996"/>
    <parent link="pelvis"/>
    <child link="vectorNav"/>
  </joint> -->

  <joint name="fixed_left" type="fixed">
    <origin rpy="0 1.57079632679 0" xyz="0.021 0.135 0"/>
    <parent link="pelvis"/>
    <child link="left_pelvis_abduction"/>
  </joint>
  <joint name="hip_abduction_left" type="continuous">
    <origin rpy="0 -1.57079632679 0" xyz="0 0 -0.07"/>
    <axis xyz="1 0 0"/>
    <parent link="left_pelvis_abduction"/>
    <child link="left_pelvis_rotation"/>
    <!-- <limit effort="4.5" lower="-0.2618" upper="0.3927" velocity="12.1475"/> -->
  </joint>
  <joint name="hip_rotation_left" type="continuous">
    <origin rpy="0 1.57079632679 -1.57079632679" xyz="0 0 -0.09"/>
    <axis xyz="-1 0 0"/>
    <parent link="left_pelvis_rotation"/>
    <child link="left_hip"/>
    <!-- <limit effort="4.5" lower="-0.3927" upper="0.3927" velocity="12.1475"/> -->
  </joint>
  <joint name="hip_flexion_left" type="continuous">
    <origin rpy="0 0 0" xyz="0 0 0"/>
    <axis xyz="0 0 1"/>
    <parent link="left_hip"/>
    <child link="left_thigh"/>
    <!-- <limit effort="12.2" lower="-0.8727" upper="1.3963" velocity="8.5085"/> -->
  </joint>
  <joint name="knee_joint_left" type="continuous">
    <origin rpy="0 0 0" xyz="0.12 0 0.0045"/>
    <axis xyz="0 0 1"/>
    <parent link="left_thigh"/>
    <child link="left_knee"/>
    <!-- <limit effort="12.2" lower="-2.8623" upper="-0.6458" velocity="8.5085"/> -->
  </joint>
  <joint name="knee_to_shin_left" type="continuous">
    <origin rpy="0 0 0" xyz="0.0607 0.0474 0"/>
    <axis xyz="0 0 1"/>
    <parent link="left_knee"/>
    <child link="left_shin"/>
    <!-- <limit effort="0" lower="-100" upper="100" velocity="100"/> -->
  </joint>
  <joint name="ankle_joint_left" type="continuous">
    <origin rpy="0 0 0" xyz="0.4348 0.02 0"/>
    <axis xyz="0 0 1"/>
    <parent link="left_shin"/>
    <child link="left_tarsus"/>
    <!-- <limit effort="0" lower="-100" upper="100" velocity="100"/> -->
  </joint>
  <joint name="toe_joint_left" type="continuous">
    <origin rpy="0 0 0" xyz="0.408 -0.04 0"/>
    <axis xyz="0 0 1"/>
    <parent link="left_tarsus"/>
    <child link="left_toe"/>
    <!-- <limit effort="0.9" lower="-2.4435" upper="-0.5236" velocity="11.5192"/> -->
  </joint>

  <joint name="fixed_right" type="fixed">
    <origin rpy="0 1.57079632679 0" xyz="0.021 -0.135 0"/>
    <parent link="pelvis"/>
    <child link="right_pelvis_abduction"/>
  </joint>
  <joint name="hip_abduction_right" type="continuous">
    <origin rpy="0 -1.57079632679 0" xyz="0 0 -0.07"/>
    <axis xyz="1 0 0"/>
    <parent link="right_pelvis_abduction"/>
    <child link="right_pelvis_rotation"/>
    <!-- <limit effort="4.5" lower="-0.3927" upper="0.2618" velocity="12.1475"/> -->
  </joint>
  <joint name="hip_rotation_right" type="continuous">
    <origin rpy="0 1.57079632679 -1.57079632679" xyz="0 0 -0.09"/>
    <axis xyz="-1 0 0"/>
    <parent link="right_pelvis_rotation"/>
    <child link="right_hip"/>
    <!-- <limit effort="4.5" lower="-0.3927" upper="0.3927" velocity="12.1475"/> -->
  </joint>
  <joint name="hip_flexion_right" type="continuous">
    <origin rpy="0 0 0" xyz="0 0 0"/>
    <axis xyz="0 0 1"/>
    <parent link="right_hip"/>
    <child link="right_thigh"/>
    <!-- <limit effort="12.2" lower="-0.8727" upper="1.3963" velocity="8.5085"/> -->
  </joint>
  <joint name="knee_joint_right" type="continuous">
    <origin rpy="0 0 0" xyz="0.12 0 -0.0045"/>
    <axis xyz="0 0 1"/>
    <parent link="right_thigh"/>
    <child link="right_knee"/>
    <!-- <limit effort="12.2" lower="-2.8623" upper="-0.6458" velocity="8.5085"/> -->
  </joint>
  <joint name="knee_to_shin_right" type="continuous">
    <origin rpy="0 0 0" xyz="0.0607 0.0474 0"/>
    <axis xyz="0 0 1"/>
    <parent link="right_knee"/>
    <child link="right_shin"/>
    <!-- <limit effort="0" lower="-100" upper="100" velocity="100"/> -->
  </joint>
  <joint name="ankle_joint_right" type="continuous">
    <origin rpy="0 0 0" xyz="0.4348 0.02 0"/>
    <axis xyz="0 0 1"/>
    <parent link="right_shin"/>
    <child link="right_tarsus"/>
    <!-- <limit effort="0" lower="-100" upper="100" velocity="100"/> -->
  </joint>
  <joint name="toe_joint_right" type="continuous">
    <origin rpy="0 0 0" xyz="0.408 -0.04 0"/>
    <axis xyz="0 0 1"/>
    <parent link="right_tarsus"/>
    <child link="right_toe"/>
    <!-- <limit effort="0.9" lower="-2.4435" upper="-0.5236" velocity="11.5192"/> -->
  </joint>
  <transmission name="hip_abduction_trans_left" type="transmission_interface/SimpleTransmission">
    <joint name="hip_abduction_left"/>
    <actuator name="hip_abduction_motor_left"/>
    <mechanicalReduction>25</mechanicalReduction>
  </transmission>
  <transmission name="hip_rotation_trans_left" type="transmission_interface/SimpleTransmission">
    <joint name="hip_rotation_left"/>
    <actuator name="hip_rotation_motor_left"/>
    <mechanicalReduction>25</mechanicalReduction>
  </transmission>
  <transmission name="hip_flexion_trans_left" type="transmission_interface/SimpleTransmission">
    <joint name="hip_flexion_left"/>
    <actuator name="hip_flexion_motor_left"/>
    <mechanicalReduction>16</mechanicalReduction>
  </transmission>
  <transmission name="knee_joint_trans_left" type="transmission_interface/SimpleTransmission">
    <joint name="knee_joint_left"/>
    <actuator name="knee_joint_motor_left"/>
    <mechanicalReduction>16</mechanicalReduction>
  </transmission>
  <transmission name="toe_joint_trans_left" type="transmission_interface/SimpleTransmission">
    <joint name="toe_joint_left"/>
    <actuator name="toe_joint_motor_left"/>
    <mechanicalReduction>50</mechanicalReduction>
  </transmission>
  <transmission name="hip_abduction_trans_right" type="transmission_interface/SimpleTransmission">
    <joint name="hip_abduction_right"/>
    <actuator name="hip_abduction_motor_right"/>
    <mechanicalReduction>25</mechanicalReduction>
  </transmission>
  <transmission name="hip_rotation_trans_right" type="transmission_interface/SimpleTransmission">
    <joint name="hip_rotation_right"/>
    <actuator name="hip_rotation_motor_right"/>
    <mechanicalReduction>25</mechanicalReduction>
  </transmission>
  <transmission name="hip_flexion_trans_right" type="transmission_interface/SimpleTransmission">
    <joint name="hip_flexion_right"/>
    <actuator name="hip_flexion_motor_right"/>
    <mechanicalReduction>16</mechanicalReduction>
  </transmission>
  <transmission name="knee_joint_trans_right" type="transmission_interface/SimpleTransmission">
    <joint name="knee_joint_right"/>
    <actuator name="knee_joint_motor_right"/>
    <mechanicalReduction>16</mechanicalReduction>
  </transmission>
  <transmission name="toe_joint_trans_right" type="transmission_interface/SimpleTransmission">
    <joint name="toe_joint_right"/>
    <actuator name="toe_joint_motor_right"/>
    <mechanicalReduction>50</mechanicalReduction>
  </transmission>
</robot>
